// piece of code which throws an error can be wrapped inside a try block
// you can catch the error with catch block


try{
    console.log(c+d)

}
catch(err){
    // console.log(err)
    console.log("there was an error")
    

}
console.log("this line now runs")

